Workbook

Sheet Sheet4
A1: New Unit | B1: (All)
A3: Count of Name | B3: Column Labels
A4: Row Labels | B4: AIRCRAFT CABIN CONTROLLER | C4: AIRCRAFT CABIN ENGINEER | D4: AIRCRAFT CABIN TECHNICIAN | E4: AIRCRAFT MAINTENANCE ENGINEER | F4: AIRCRAFT MAINTENANCE PLANNER | G4: AIRCRAFT MAINTENANCE TECHNICIAN | H4: ASSISTANT STAFF OFFICER | I4: OJT TO AIRCRAFT CABIN ENGINEER | J4: SENIOR AIRCRAFT CABIN CONTROLLER | K4: SENIOR AIRCRAFT CABIN ENGINEER | L4: SENIOR AIRCRAFT CABIN TECHNICIAN | M4: SENIOR AIRCRAFT MAINTENANCE PLANNER | N4: SENIOR AIRCRAFT MAINTENANCE PLANNING ENGINEER | O4: SENIOR AIRCRAFT MAINTENANCE TECHNICIAN | P4: Group Head | Q4: SECRETARY | R4: Division Head | S4: Department Head | T4: Aircraft Cabin Technician (PKWT NP) | U4: AIRCRAFT MAINTENANCE TECHNICIAN (PKWT NP) | V4: MANAGER CABIN ON DUTY | W4: AIRCRAFT MAINTENANCE PLANNING ENGINEER | X4: Grand Total
A5: 1 | B5: 1 | C5: 22 | D5: 2 | E5: 3 | F5: 1 | G5: 2 | H5: 2 | J5: 8 | K5: 2 | L5: 21 | M5: 5 | N5: 3 | O5: 30 | P5: 1 | Q5: 1 | R5: 2 | S5: 9 | T5: 43 | U5: 2 | V5: 4 | X5: 164
A6: 0.93333333 | C6: 6 | I6: 1 | O6: 7 | X6: 14
A7: 0.92307692 | L7: 15 | X7: 15
A8: 0.86666667 | O8: 1 | X8: 1
A9: 0.8 | O9: 1 | X9: 1
A10: 0.92857143 | F10: 1 | S10: 1 | W10: 1 | X10: 3
A11: 0.85714286 | S11: 1 | X11: 1
A12: 0.76923077 | L12: 2 | X12: 2
A13: 0.88888889 | V13: 1 | X13: 1
A14: 0.84615385 | L14: 2 | X14: 2
A15: 0.53846154 | L15: 2 | X15: 2
A16: 0.69230769 | L16: 1 | X16: 1
A17: 0.61538462 | L17: 1 | X17: 1
A18: 0.13333333 | C18: 1 | X18: 1
A19: Grand Total | B19: 1 | C19: 29 | D19: 2 | E19: 3 | F19: 2 | G19: 2 | H19: 2 | I19: 1 | J19: 8 | K19: 2 | L19: 44 | M19: 5 | N19: 3 | O19: 39 | P19: 1 | Q19: 1 | R19: 2 | S19: 11 | T19: 43 | U19: 2 | V19: 5 | W19: 1 | X19: 209

Sheet Dashboard
A1: Training Type | B1: Valid | C1: Expired | D1: Expiring | E1: Not Trained
A2: Human Factor | B2: =COUNTIF(TrainingData!$I:$I,B$1) -> 193 | C2: =COUNTIF(TrainingData!$I:$I,C$1) -> 0 | D2: =COUNTIF(TrainingData!$I:$I,D$1) -> 11 | E2: =COUNTIF(TrainingData!$I:$I,E$1) -> 3 | F2: =SUM(B2:E2) -> 207
A3: Safety Management System | B3: =COUNTIF(TrainingData!$K:$K,B$1) -> 193 | C3: =COUNTIF(TrainingData!$K:$K,C$1) -> 0 | D3: =COUNTIF(TrainingData!$K:$K,D$1) -> 12 | E3: =COUNTIF(TrainingData!$K:$K,E$1) -> 2 | F3: =SUM(B3:E3) -> 207
A4: GMF Quality System | B4: =COUNTIF(TrainingData!$M:$M,B$1) -> 188 | C4: =COUNTIF(TrainingData!$M:$M,C$1) -> 7 | D4: =COUNTIF(TrainingData!$M:$M,D$1) -> 10 | E4: =COUNTIF(TrainingData!$M:$M,E$1) -> 2 | F4: =SUM(B4:E4) -> 207
A5: CASR Part 145 | B5: =COUNTIF(TrainingData!$O:$O,B$1) -> 138 | C5: =COUNTIF(TrainingData!$O:$O,C$1) -> 8 | D5: =COUNTIF(TrainingData!$O:$O,D$1) -> 12 | E5: =COUNTIF(TrainingData!$O:$O,E$1) -> 1 | F5: =SUM(B5:E5) -> 159
A6: FAR Part 145 | B6: =COUNTIF(TrainingData!$Q:$Q,B$1) -> 135 | C6: =COUNTIF(TrainingData!$Q:$Q,C$1) -> 8 | D6: =COUNTIF(TrainingData!$Q:$Q,D$1) -> 15 | E6: =COUNTIF(TrainingData!$Q:$Q,E$1) -> 1 | F6: =SUM(B6:E6) -> 159
A7: EASA Part 145 | B7: =COUNTIF(TrainingData!$S:$S,B$1) -> 138 | C7: =COUNTIF(TrainingData!$S:$S,C$1) -> 9 | D7: =COUNTIF(TrainingData!$S:$S,D$1) -> 11 | E7: =COUNTIF(TrainingData!$S:$S,E$1) -> 1 | F7: =SUM(B7:E7) -> 159
A8: EASA Part M | B8: =COUNTIF(TrainingData!$U:$U,B$1) -> 140 | C8: =COUNTIF(TrainingData!$U:$U,C$1) -> 8 | D8: =COUNTIF(TrainingData!$U:$U,D$1) -> 10 | E8: =COUNTIF(TrainingData!$U:$U,E$1) -> 1 | F8: =SUM(B8:E8) -> 159
A9: Fuel Tank Safety | B9: =COUNTIF(TrainingData!$W:$W,B$1) -> 140 | C9: =COUNTIF(TrainingData!$W:$W,C$1) -> 6 | D9: =COUNTIF(TrainingData!$W:$W,D$1) -> 12 | E9: =COUNTIF(TrainingData!$W:$W,E$1) -> 1 | F9: =SUM(B9:E9) -> 159
A10: EWIS | B10: =COUNTIF(TrainingData!$Y:$Y,B$1) -> 143 | C10: =COUNTIF(TrainingData!$Y:$Y,C$1) -> 4 | D10: =COUNTIF(TrainingData!$Y:$Y,D$1) -> 8 | E10: =COUNTIF(TrainingData!$Y:$Y,E$1) -> 4 | F10: =SUM(B10:E10) -> 159
A11: Dangerous Good | B11: =COUNTIF(TrainingData!$AA:$AA,B$1) -> 154 | C11: =COUNTIF(TrainingData!$AA:$AA,C$1) -> 0 | D11: =COUNTIF(TrainingData!$AA:$AA,D$1) -> 0 | E11: =COUNTIF(TrainingData!$AA:$AA,E$1) -> 5 | F11: =SUM(B11:E11) -> 159
B12: =SUM(B2:B11) -> 1562 | C12: =SUM(C2:C11) -> 50 | D12: =SUM(D2:D11) -> 101 | E12: =SUM(E2:E11) -> 21 | F12: =SUM(F2:F11) -> 1734
B13: =(B12+D12)/F12 -> 0.95905421
B18: Valid | C18: Expired | D18: Expiring | E18: Not Trained
A19: AMEL | B19: =COUNTIF(TrainingData!$CE:$CE,B$1) -> 64 | C19: =COUNTIF(TrainingData!$CE:$CE,C$1) -> 3 | D19: =COUNTIF(TrainingData!$CE:$CE,D$1) -> 9 | E19: =COUNTIF(TrainingData!$CE:$CE,E$1) -> 131 | F19: =SUM(B19:E19) -> 207
A20: Stamp | B20: =COUNTIF(TrainingData!$CH:$CH,B$1) -> 111 | C20: =COUNTIF(TrainingData!$CH:$CH,C$1) -> 0 | D20: =COUNTIF(TrainingData!$CH:$CH,D$1) -> 0 | E20: =COUNTIF(TrainingData!$CH:$CH,E$1) -> 91 | F20: =SUM(B20:E20) -> 202
B21: =SUM(B19:B20) -> 175 | C21: =SUM(C19:C20) -> 3 | D21: =SUM(D19:D20) -> 9 | E21: =SUM(E19:E20) -> 222

Sheet Sheet2
A3: Row Labels | B3: Count of New Unit
A4: JKTTN | B4: 2
A5: JKTTNL | B5: 1
A6: JKTTNL-1 | B6: 19
A7: JKTTNL-2 | B7: 19
A8: JKTTNL-3 | B8: 19
A9: JKTTNL-4 | B9: 19
A10: JKTTNL-5 | B10: 19
A11: JKTTNL-6 | B11: 65
A12: JKTTNL-7 | B12: 9
A13: JKTTNP | B13: 6
A14: JKTTNP-1 | B14: 10
A15: JKTTNP-2 | B15: 13
... A18: Grand Total | B18: 209

Sheet Pivot
K1: Type Rating Level III Training | O1: AMEL | S1: I Stamp
K2: Job Title | L2: (Multiple Items) | O2: New Unit | P2: (Multiple Items) | S2: New Unit | T2: (Multiple Items)
K3: Type Rating Level III Training | L3: (blank) | O3: AMEL No | P3: (blank) | S3: AMEL No | T3: (Multiple Items)
I4: =GETPIVOTDATA("3",$G$3,"3","A320 Neo") -> #REF! | K4: New Unit | L4: (Multiple Items) | O4: Job Title | P4: (Multiple Items) | S4: Job Title | T4: (Multiple Items)
I5: =GETPIVOTDATA("3",$G$3,"3","A330 NEO") -> #REF! | K5: Stamp No | L5: (Multiple Items) | O5: Type Rating Level III Training | P5: (Multiple Items) | S5: Stamp No | T5: (Multiple Items)
I6: =GETPIVOTDATA("3",$G$3,"3","A330 Neo, A320 Neo")-GETPIVOTDATA("AMEL 3",$G$20,"AMEL 3","A330 Neo, A320 Neo") -> #REF!
I7: =GETPIVOTDATA("3",$G$3,"3","B737 MAX") -> #REF! | K7: Row Labels | L7: Count of Type Rating Level III Training | O7: Row Labels | P7: Count of AMEL No | S7: Row Labels
I8: =GETPIVOTDATA("3",$G$3,"3","CRJ")-GETPIVOTDATA("AMEL 3",$G$20,"AMEL 3","CRJ") -> #REF! | K8: ARFIN SENO HASTIAN | O8: AMRIZAL GUSFANI | S8: ARIF FIKRY ABDUL MUBAROK
K9: BAYU HANDOYO | O9: DINANDA AGIL PRAKOSO | S9: ARIFIN
K10: DAFFA HAUZAN | O10: FAJRIN SARSONO | S10: DIMAS ANGGORO
K11: DIMAS SURYO PERSODO | O11: FIQRI RAKA FADILLAH | S11: ENGGAR DWI KUNCORO
K12: FEBI FERDIANSYAH | O12: GENTA PRAMUDITA | S12: JAMALLULLAEL NILAI BASTANTA BONANI PASOGIT
K13: MEILINDA SURYANI | O13: MUHAMMAD LUTHFI WIDIANTO | S13: M. ASIS
K14: OSSA FAUZI | O14: PANGERAN RAIHAN RANGKUTI | S14: RIZKY FAUZI
K15: RIZAL AZIS | O15: RADEN RUDIANSYAH | S15: YONAZ HAND
K16: Grand Total | O16: RAKHA VIVALDI NOVALLINO | S16: Grand Total
O17: RISKY SAPUTRA ARMAN
O18: RONY ERYA WARDANA
K19: Row Labels | L19: Count of Type Rating Level III Training | O19: SATRIA WIJAYANTO
K20: ARFIN SENO HASTIAN | L20: Tdk punya GL | O20: YANA SUPRIATNA
K21: BAYU HANDOYO | L21: Tdk punya GL | O21: YOGI CATUR
K22: DAFFA HAUZAN | L22: Tdk punya GL | O22: Grand Total
K23: DIMAS SURYO PERSODO | L23: Tdk punya GL
K24: FEBI FERDIANSYAH | L24: Tdk punya GL
K25: MEILINDA SURYANI | L25: Punya GL
K26: OSSA FAUZI | L26: Tdk punya GL
K27: RIZAL AZIS | L27: Tdk punya GL
A31: M STAMP
A32: New Unit | B32: (Multiple Items) | D32: M Stamp | E32: =COUNTA(A37:A42) -> 6 | O32: Row Labels | P32: Count of AMEL No | Q32: Status
A33: Job Title | B33: (Multiple Items) | D33: Type Rating | E33: =COUNTA(K8:K15) -> 8 | O33: AMRIZAL GUSFANI | Q33: Menunggu dameer
A34: Stamp No | B34: (blank) | D34: AMEL | E34: =COUNTA(O8:O26) -> 15 | O34: DANAN TRIAWAN | Q34: Assessment tgl 10 Nov
D35: I Stamp | E35: =COUNTA(S8:S15) -> 8 | O35: DINANDA AGIL PRAKOSO | Q35: STE 50%
A36: Row Labels | B36: Count of Stamp No | O36: FAJRIN SARSONO | Q36: Progress, janji akhir tahun apply
A37: ACHMAD FAHRUL AMRY | O37: FIQRI RAKA FADILLAH
A38: DWIKI FAHREZA ANDREANTO | O38: GENTA PRAMUDITA | Q38: Progres pengajuan, ada revisi PEL, waiting update
A39: JAVIER BENYAMIN CASSANOVA TALAKUA | O39: ILHAM NUGRAHA | Q39: Assessment 3 Des
A40: MUHAMAD DUSTIRANSA TAQWA | O40: M FIKRI ADRIAN | Q40: Assessment 3 Des | S40: Sudah Rating B737 tapi GL baru terbit, Tanggal Penerbitan tidak sesuai dengan tanggal lulus karena baru diajukan oleh THW
A41: MUHAMMAD RINALDI HIDAYAT | O41: MUHAMMAD LUTHFI WIDIANTO | Q41: Expired Need Refreshing
A42: RINDA SAFANA LINGGI | O42: PANGERAN RAIHAN RANGKUTI | Q42: GL Fisik Tidak ada
A43: AJI SATRIO RAMADHAN | O43: PEGGY ASRUL SANI | Q43: Assessment tgl 14 Nov
...

Sheet Pivot AMEL
L1: Typ | M1: 2 | N1: 1 | O1: 3 | P1: Total
L2: A330 | M2: 1 | N2: =GETPIVOTDATA("AMEL 1",$A$20,"AMEL 1","A330") -> 28 | P2: =SUM(M2:O2) -> 29
A3: Row Labels | B3: Count of 1 | D3: Row Labels | E3: Count of 2 | G3: Row Labels | H3: Count of 3 | L3: B737 | M3: 1 | N3: =GETPIVOTDATA("AMEL 1",$A$20,"AMEL 1","B737") -> 24 | P3: =SUM(M3:O3) -> 25
A4: A320 | B4: 22 | D4: A320 | E4: 9 | G4: A320 Neo | H4: 2 | I4: =GETPIVOTDATA("3",$G$3,"3","A320 Neo") -> 2 | L4: A320 | M4: 6 | N4: =GETPIVOTDATA("AMEL 1",$A$20,"AMEL 1","A320") -> 16 | P4: =SUM(M4:O4) -> 22
A5: A330 | B5: 31 | D5: A320 Neo | E5: 10 | G5: A330 NEO | H5: 1 | I5: =GETPIVOTDATA("3",$G$3,"3","A330 NEO") -> 1 | L5: A330 Neo | M5: 10 | O5: =GETPIVOTDATA("AMEL 3",$G$20,"AMEL 3","A330 Neo, A320 Neo") -> 1 | P5: =SUM(M5:O5) -> 11
A6: ATR | B6: 3 | D6: A330 | E6: 3 | G6: A330 Neo, A320 Neo | H6: 1 | I6: =GETPIVOTDATA("3",$G$3,"3","A330 Neo, A320 Neo")-GETPIVOTDATA("AMEL 3",$G$20,"AMEL 3","A330 Neo, A320 Neo") -> 0 | L6: B777 | M6: 1 | N6: =GETPIVOTDATA("AMEL 1",$A$20,"AMEL 1","B777") -> 9 | P6: =SUM(M6:O6) -> 10
A7: B737 | B7: 26 | D7: A330 Neo | E7: 16 | G7: B737 MAX | H7: 1 | I7: =GETPIVOTDATA("3",$G$3,"3","B737 MAX") -> 1 | L7: A320 Neo | M7: 6 | O7: =GETPIVOTDATA("AMEL 3",$G$20,"AMEL 3","A330 Neo, A320 Neo") -> 1 | P7: =SUM(M7:O7) -> 7
A8: B777 | B8: 12 | D8: ATR | E8: 2 | G8: CRJ | H8: 1 | I8: =GETPIVOTDATA("3",$G$3,"3","CRJ")-GETPIVOTDATA("AMEL 3",$G$20,"AMEL 3","CRJ") -> 0 | L8: CRJ | M8: 1 | N8: =GETPIVOTDATA("AMEL 1",$A$20,"AMEL 1","CRJ") -> 3 | O8: =GETPIVOTDATA("AMEL 3",$G$20,"AMEL 3","CRJ") -> 1 | P8: =SUM(M8:O8) -> 5
A9: CRJ | B9: 3 | D9: B737 | E9: 2 | G9: (blank) | L9: ATR | M9: 1 | N9: =GETPIVOTDATA("AMEL 1",$A$20,"AMEL 1","ATR") -> 3 | P9: =SUM(M9:O9) -> 4
A10: (blank) | D10: B737 Max | E10: 2 | G10: Grand Total | H10: 6 | L10: B737 Max | M10: 1 | P10: =SUM(M10:O10) -> 1
A11: Grand Total | B11: 97 | D11: B777 | E11: 4
D12: CRJ | E12: 1
D13: (blank)
D14: Grand Total | E14: 49
A20: Row Labels | B20: Count of AMEL 1 | D20: Row Labels | E20: Count of AMEL 2 | G20: Row Labels | H20: Count of AMEL 3
A21: A320 | B21: 16 | C21: =GETPIVOTDATA("1",$A$3,"1","A320")-GETPIVOTDATA("AMEL 1",$A$20,"AMEL 1","A320") -> 6 | D21: A320 | E21: 6 | F21: =GETPIVOTDATA("2",$D$3,"2","A320")-GETPIVOTDATA("AMEL 2",$D$20,"AMEL 2","A320") -> 3 | G21: A330 Neo, A320 Neo | H21: 1
A22: A330 | B22: 28 | C22: =GETPIVOTDATA("1",$A$3,"1","A330")-GETPIVOTDATA("AMEL 1",$A$20,"AMEL 1","A330") -> 3 | D22: A320 Neo | E22: 6 | F22: =GETPIVOTDATA("2",$D$3,"2","A320 Neo")-GETPIVOTDATA("AMEL 2",$D$20,"AMEL 2","A320 Neo") -> 4 | G22: CRJ | H22: 1
A23: ATR | B23: 3 | C23: =GETPIVOTDATA("1",$A$3,"1","ATR")-GETPIVOTDATA("AMEL 1",$A$20,"AMEL 1","ATR") -> 0 | D23: A330 | E23: 1 | F23: =GETPIVOTDATA("2",$D$3,"2","A330")-GETPIVOTDATA("AMEL 2",$D$20,"AMEL 2","A330") -> 2 | G23: (blank)
A24: B737 | B24: 24 | C24: =GETPIVOTDATA("1",$A$3,"1","B737")-GETPIVOTDATA("AMEL 1",$A$20,"AMEL 1","B737") -> 2 | D24: A330 Neo | E24: 10 | F24: =GETPIVOTDATA("2",$D$3,"2","A330 Neo")-GETPIVOTDATA("AMEL 2",$D$20,"AMEL 2","A330 Neo") -> 6 | G24: Grand Total | H24: 2
A25: B777 | B25: 9 | C25: =GETPIVOTDATA("1",$A$3,"1","B777")-GETPIVOTDATA("AMEL 1",$A$20,"AMEL 1","B777") -> 3 | D25: ATR | E25: 1 | F25: =GETPIVOTDATA("2",$D$3,"2","ATR")-GETPIVOTDATA("AMEL 2",$D$20,"AMEL 2","ATR") -> 1
A26: CRJ | B26: 3 | C26: =GETPIVOTDATA("1",$A$3,"1","CRJ")-GETPIVOTDATA("AMEL 1",$A$20,"AMEL 1","CRJ") -> 0 | D26: B737 | E26: 1 | F26: =GETPIVOTDATA("2",$D$3,"2","B737")-GETPIVOTDATA("AMEL 2",$D$20,"AMEL 2","B737") -> 1
A27: (blank) | D27: B737 Max | E27: 1 | F27: =GETPIVOTDATA("2",$D$3,"2","B737 Max")-GETPIVOTDATA("AMEL 2",$D$20,"AMEL 2","B737 Max") -> 1
A28: Grand Total | B28: 83 | D28: B777 | E28: 1 | F28: =GETPIVOTDATA("2",$D$3,"2","B777")-GETPIVOTDATA("AMEL 2",$D$20,"AMEL 2","B777") -> 3
D29: CRJ | E29: 1 | F29: =GETPIVOTDATA("2",$D$3,"2","CRJ")-GETPIVOTDATA("AMEL 2",$D$20,"AMEL 2","CRJ") -> 0
D30: (blank)
D31: Grand Total | E31: 28
A34: A320 | B34: 6 | C34: =GETPIVOTDATA("AMEL 1",$A$20,"AMEL 1","A320") -> 16 | E34: =SUM(B34:D34) -> 22
A35: A320 Neo | B35: 6 | D35: =GETPIVOTDATA("AMEL 3",$G$20,"AMEL 3","A330 Neo, A320 Neo") -> 1 | E35: =SUM(B35:D35) -> 7
A36: A330 | B36: 1 | C36: =GETPIVOTDATA("AMEL 1",$A$20,"AMEL 1","A330") -> 28 | E36: =SUM(B36:D36) -> 29
A37: A330 Neo | B37: 10 | D37: =GETPIVOTDATA("AMEL 3",$G$20,"AMEL 3","A330 Neo, A320 Neo") -> 1 | E37: =SUM(B37:D37) -> 11
A38: ATR | B38: 1 | C38: =GETPIVOTDATA("AMEL 1",$A$20,"AMEL 1","ATR") -> 3 | E38: =SUM(B38:D38) -> 4
A39: B737 | B39: 1 | C39: =GETPIVOTDATA("AMEL 1",$A$20,"AMEL 1","B737") -> 24 | E39: =SUM(B39:D39) -> 25
A40: B737 Max | B40: 1 | E40: =SUM(B40:D40) -> 1
A41: B777 | B41: 1 | C41: =GETPIVOTDATA("AMEL 1",$A$20,"AMEL 1","B777") -> 9 | E41: =SUM(B41:D41) -> 10
A42: CRJ | B42: 1 | C42: =GETPIVOTDATA("AMEL 1",$A$20,"AMEL 1","CRJ") -> 3 | D42: =GETPIVOTDATA("AMEL 3",$G$20,"AMEL 3","CRJ") -> 1 | E42: =SUM(B42:D42) -> 5
A43: (blank)

Sheet Sheet3
A3: Count of AMEL 1 | B3: Column Labels
A4: Row Labels | B4: A320 | C4: A330 | D4: ATR | E4: B737 | F4: B777 | G4: CRJ | H4: (blank) | I4: Grand Total
A5: JKTTN
A6: JKTTNL
A7: JKTTNL-1 | B7: 1 | C7: 3 | E7: 3 | F7: 2 | G7: 1 | I7: 10
A8: JKTTNL-2 | B8: 3 | C8: 5 | D8: 1 | E8: 2 | F8: 1 | I8: 12
A9: JKTTNL-3 | B9: 3 | C9: 2 | D9: 1 | E9: 4 | F9: 1 | I9: 11
A10: JKTTNL-4 | B10: 1 | C10: 3 | D10: 1 | E10: 3 | F10: 2 | I10: 10
A11: JKTTNL-5 | B11: 4 | C11: 4 | E11: 3 | F11: 1 | I11: 12
A12: JKTTNL-6 | B12: 4 | C12: 7 | E12: 6 | F12: 1 | G12: 1 | I12: 19
A13: JKTTNL-7 | C13: 1 | I13: 1
A14: JKTTNP | C14: 2 | G14: 1 | I14: 3
A15: JKTTNP-1
A16: JKTTNP-2
A17: JKTTNP-3 | C17: 1 | E17: 3 | F17: 1 | I17: 5
A18: JKTTNP-4
A19: Grand Total | B19: 16 | C19: 28 | D19: 3 | E19: 24 | F19: 9 | G19: 3 | I19: 83
A23: Count of AMEL 1 | B23: Column Labels
A24: Row Labels | B24: A320 | C24: A330 | D24: ATR | E24: B737 | F24: B777 | G24: CRJ | H24: (blank) | I24: Grand Total
A25: JKTTN
A26: JKTTNL
A27: JKTTNL-1 | B27: 1 | C27: 3 | E27: 3 | F27: 2 | G27: 1 | I27: 10
A28: JKTTNL-2 | B28: 3 | C28: 5 | D28: 1 | E28: 2 | F28: 1 | I28: 12
A29: JKTTNL-3 | B29: 3 | C29: 2 | D29: 1 | E29: 4 | F29: 1 | I29: 11
A30: JKTTNL-4 | B30: 1 | C30: 3 | D30: 1 | E30: 3 | F30: 2 | I30: 10
A31: JKTTNL-5 | B31: 4 | C31: 4 | E31: 3 | F31: 1 | I31: 12
A32: JKTTNL-6 | B32: 4 | C32: 7 | E32: 6 | F32: 1 | G32: 1 | I32: 19
A33: JKTTNL-7 | C33: 1 | I33: 1
A34: JKTTNP | C34: 2 | G34: 1 | I34: 3
A35: JKTTNP-1
A36: JKTTNP-2
A37: JKTTNP-3 | C37: 1 | E37: 3 | F37: 1 | I37: 5
A38: JKTTNP-4
A39: Grand Total | B39: 16 | C39: 28 | D39: 3 | E39: 24 | F39: 9 | G39: 3 | I39: 83

Sheet TrainingData
A2: No | B2: Emp ID | C2: Name | D2: Job Title | E2: Group | F2: Unit | G2: New Unit | H2: Human Factor | I2: HF Status | J2: Safety Management System | K2: SMS Status | L2: GMF Quality System | M2: QS Status | N2: CASR Part 145 | O2: CASR Status | P2: FAR Part 145 | Q2: FAR Status | R2: EASA Part 145 | S2: EASA Status | T2: EASA Part M | U2: Part M Status | V2: Fuel Tank Safety | W2: FTS Status | X2: EWIS | Y2: EWIS Status | Z2: Dangerous Good | AA2: DG Status | AB2: ADTH | AC2: Basic Inspection | AD2: Basic Supervisory Training | AE2: Certifying Staff | AF2: Fundamental Troubleshooting | AG2: Training of Trainer | AH2: Basic Planning | AI2: Basic Engineering | AJ2: Aircraft Familiarization | AK2: GMF Logistic Business | AL2: Warehouse Management | AM2: Material Handling | AN2: Aircraft Exterior & Interior Cleaning | AO2: GSE Type Rating | AP2: Aviation Legislation Module 10 | AQ2: Leadership Skill Training | AR2: MRO Management | AS2: MRO Finance | AT2: Project Management basic | AU2: OLP | AV2: Office Administration | AW2: Basic Accounting Module | AX2: Service Excelent | AY2: Management for Secretary | AZ2: RII | BA2: Lead Auditor Course | BB2: SWIFT Training | BC2: IFE | BD2: Orientation Training | BE2: BCT | BF2: BAM | BG2: BATK | BH2: GAK | BI2: Type Rating Level III Training | BJ2: 1 | BK2: 2 | BL2: 3 | BM2: Simplified Technical English | BN2: Radio Telephony | BO2: B737 BCF | BP2: Mandatory for Supporting | BQ2: Req Training | BR2: Completed Training | BS2: Achievement | BT2: Training Achivement | BU2: Employee Category | BV2: General Lic. | BW2: AMEL 1 | BX2: AMEL 2 | BY2: AMEL 3 | BZ2: AMEL No | CA2: AMEL Qty | CB2: CS No | CC2: Stamp No | CD2: AMEL Validity | CE2: AMEL Status | CF2: CS Validity | CG2: Stamp Validity | CH2: Stamp Status | CI2: Eligibility ACE | CJ2: Eligibility SACE
A3: 1 | B3: 533380 | C3: DIAHYANI PUTRI | D3: Group Head | E3: p401 | F3: JKTTLF | G3: JKTTN | H3: 46925 | I3: =IF( _xlfn.XLOOKUP($D3 & "-" & H$2, 'TrainingReq (Ach)'!G:G, 'TrainingReq (Ach)'!F:F, "2-Year") = "Forever", "Valid", IF(H3="", "Not Trained", IF(H3 < TODAY() - 1, "Expired", IF(H3 <= TODAY() + 90, "Expiring", "Valid") ) ) ) -> Valid | J3: 46925 | K3: =IF( _xlfn.XLOOKUP($D3 & "-" & J$2, 'TrainingReq (Ach)'!G:G, 'TrainingReq (Ach)'!F:F, "2-Year") = "Forever", "Valid", IF(J3="", "Not Trained", IF(J3 < TODAY() - 1, "Expired", IF(J3 <= TODAY() + 90, "Expiring", "Valid") ) ) ) -> Valid | L3: 44692 | M3: =IF( _xlfn.XLOOKUP($D3 & "-" & L$2, TrainingMan!$G:$G, TrainingMan!$F:$F, "2-Year") = "Forever", "Valid", IF(L3="", "Not Trained", IF(L3 < TODAY() - 1, "Expired", IF(L3 <= TODAY() + 90, "Expiring", "Valid") ) ) ) -> Valid | O3: =IF( _xlfn.XLOOKUP($D3 & "-" & N$2, TrainingMan!$G:$G, TrainingMan!$F:$F, "2-Year") = "Forever", "Valid", IF(N3="", "Not Trained", IF(N3 < TODAY() - 1, "Expired", IF(N3 <= TODAY() + 90, "Expiring", "Valid") ) ) ) -> Valid | Q3: =IF( _xlfn.XLOOKUP($D3 & "-" & P$2, TrainingMan!$G:$G, TrainingMan!$F:$F, "2-Year") = "Forever", "Valid", IF(P3="", "Not Trained", IF(P3 < TODAY() - 1, "Expired", IF(P3 <= TODAY() + 90, "Expiring", "Valid") ) ) ) -> Valid | S3: =IF( _xlfn.XLOOKUP($D3 & "-" & R$2, TrainingMan!$G:$G, TrainingMan!$F:$F, "2-Year") = "Forever", "Valid", IF(R3="", "Not Trained", IF(R3 < TODAY() - 1, "Expired", IF(R3 <= TODAY() + 90, "Expiring", "Valid") ) ) ) -> Valid | T3: 42450 | U3: =IF( _xlfn.XLOOKUP($D3 & "-" & T$2, TrainingMan!$G:$G, TrainingMan!$F:$F, "2-Year") = "Forever", "Valid", IF(T3="", "Not Trained", IF(T3 < TODAY() - 1, "Expired", IF(T3 <= TODAY() + 90, "Expiring", "Valid") ) ) ) -> Valid | V3: 42352 | W3: =IF( _xlfn.XLOOKUP($D3 & "-" & V$2, TrainingMan!$G:$G, TrainingMan!$F:$F, "2-Year") = "Forever", "Valid", IF(V3="", "Not Trained", IF(V3 < TODAY() - 1, "Expired", IF(V3 <= TODAY() + 90, "Expiring", "Valid") ) ) ) -> Valid | Y3: =IF( _xlfn.XLOOKUP($D3 & "-" & X$2, TrainingMan!$G:$G, TrainingMan!$F:$F, "2-Year") = "Forever", "Valid", IF(X3="", "Not Trained", IF(X3 < TODAY() - 1, "Expired", IF(X3 <= TODAY() + 90, "Expiring", "Valid") ) ) ) -> Valid | Z3: 42367 | AA3: =IF(LEN(TRIM(Z3)) = 0, "Not Trained", IF(_xlfn.XLOOKUP($D3 & "-" & Z$2, TrainingMan!$G:$G, TrainingMan!$F:$F, "2-Year") = "Forever", "Valid", IF(Z3 < TODAY() - 1, "Expired", IF(Z3 <= TODAY() + 90, "Expiring", "Valid") ) ) ) -> Valid | AQ3: 43203 | AS3: 45073 | AZ3: 2012-09-20 | BA3: 2012-04-04 | BD3: 2024-12-31 | BG3: 40735 | BQ3: =COUNTIF('TrainingReq (Ach)'!B:B,Table13[[#This Row],[Job Title]]) -> 2 | BR3: {=SUMPRODUCT( COUNTIFS( ValidityMatrix[Job Title], Table13[[#This Row],[Job Title]], ValidityMatrix[Training Type], Table13[[#Headers],[Human Factor]:[Mandatory for Supporting]] ), --(Table13[[#This Row],[Human Factor]:[Mandatory for Supporting]]<>""), --(Table13[[#This Row],[Human Factor]:[Mandatory for Supporting]]<>"Not Trained") )} -> 2 | BS3: =BR3/BQ3 -> 1 | BT3: 75.00% | BU3: INDIRECT | CE3: =IF( _xlfn.XLOOKUP($D3 & "-" & CD$2, 'TrainingReq (Ach)'!$G:$G, 'TrainingReq (Ach)'!$F:$F, "2-Year") = "Forever", "Valid", IF(CD3="", "Not Trained", IF(CD3 < TODAY() - 1, "Expired", IF(CD3 <= TODAY() + 90, "Expiring", "Valid") ) ) ) -> Not Trained | CF3: null | CH3: =IF( _xlfn.XLOOKUP($D3 & "-" & CF$2, '[1]TrainingReq (Ach)'!$G:$G, '[1]TrainingReq (Ach)'!$F:$F, "2-Year") = "Forever", "Valid", IF(CF3="", "Not Trained", IF(CF3 < TODAY() - 1, "Expired", IF(CF3 <= TODAY() + 90, "Expiring", "Valid") ) ) ) -> Valid | CI3: =IF(BW3<>"","Eligible","Not eligible") -> Not eligible | CJ3: =IF(BX3<>"","Eligible","Not eligible") -> Not eligible
A4: 2 | B4: 783543 | C4: YULIA IRAWATI | D4: SECRETARY | G4: JKTTN | H4: 46655 | I4: =IF( _xlfn.XLOOKUP($D4 & "-" & H$2, 'TrainingReq (Ach)'!G:G, 'TrainingReq (Ach)'!F:F, "2-Year") = "Forever", "Valid", IF(H4="", "Not Trained", IF(H4 < TODAY() - 1, "Expired", IF(H4 <= TODAY() + 90, "Expiring", "Valid") ) ) ) -> Valid | J4: 46655 | K4: =IF( _xlfn.XLOOKUP($D4 & "-" & J$2, 'TrainingReq (Ach)'!G:G, 'TrainingReq (Ach)'!F:F, "2-Year") = "Forever", "Valid", IF(J4="", "Not Trained", IF(J4 < TODAY() - 1, "Expired", IF(J4 <= TODAY() + 90, "Expiring", "Valid") ) ) ) -> Valid | L4: 46655 | M4: =IF( _xlfn.XLOOKUP($D4 & "-" & L$2, TrainingMan!$G:$G, TrainingMan!$F:$F, "2-Year") = "Forever", "Valid", IF(L4="", "Not Trained", IF(L4 < TODAY() - 1, "Expired", IF(L4 <= TODAY() + 90, "Expiring", "Valid") ) ) ) -> Valid | BD4: 45965 | BH4: 46041 | BQ4: =COUNTIF('TrainingReq (Ach)'!B:B,Table13[[#This Row],[Job Title]]) -> 3 | BR4: {=SUMPRODUCT( COUNTIFS( ValidityMatrix[Job Title], Table13[[#This Row],[Job Title]], ValidityMatrix[Training Type], Table13[[#Headers],[Human Factor]:[Mandatory for Supporting]] ), --(Table13[[#This Row],[Human Factor]:[Mandatory for Supporting]]<>""), --(Table13[[#This Row],[Human Factor]:[Mandatory for Supporting]]<>"Not Trained") )} -> 3 | BS4: =BR4/BQ4 -> 1 | CE4: =IF( _xlfn.XLOOKUP($D4 & "-" & CD$2, 'TrainingReq (Ach)'!$G:$G, 'TrainingReq (Ach)'!$F:$F, "2-Year") = "Forever", "Valid", IF(CD4="", "Not Trained", IF(CD4 < TODAY() - 1, "Expired", IF(CD4 <= TODAY() + 90, "Expiring", "Valid") ) ) ) -> Not Trained | CH4: =IF( _xlfn.XLOOKUP($D3 & "-" & CG$2, 'TrainingReq (Ach)'!$G:$G, 'TrainingReq (Ach)'!$F:$F, "2-Year") = "Forever", "Valid", IF(CG3="", "Not Trained", IF(CG3 < TODAY() - 1, "Expired", IF(CG3 <= TODAY() + 90, "Expiring", "Valid") ) ) ) -> Not Trained | CI4: =IF(BW4<>"","Eligible","Not eligible") -> Not eligible | CJ4: =IF(BX4<>"","Eligible","Not eligible") -> Not eligible
A5: 3 | B5: 532995 | C5: ARYO BAGUS SAMUDRO | D5: Division Head | G5: JKTTNL | H5: 46288 | I5: =IF( _xlfn.XLOOKUP($D5 & "-" & H$2, 'TrainingReq (Ach)'!G:G, 'TrainingReq (Ach)'!F:F, "2-Year") = "Forever", "Valid", IF(H5="", "Not Trained", IF(H5 < TODAY() - 1, "Expired", IF(H5 <= TODAY() + 90, "Expiring", "Valid") ) ) ) -> Expiring | J5: 46288 | K5: =IF( _xlfn.XLOOKUP($D5 & "-" & J$2, 'TrainingReq (Ach)'!G:G, 'TrainingReq (Ach)'!F:F, "2-Year") = "Forever", "Valid", IF(J5="", "Not Trained", IF(J5 < TODAY() - 1, "Expired", IF(J5 <= TODAY() + 90, "Expiring", "Valid") ) ) ) -> Expiring | L5: 43370 | M5: =IF( _xlfn.XLOOKUP($D5 & "-" & L$2, TrainingMan!$G:$G, TrainingMan!$F:$F, "2-Year") = "Forever", "Valid", IF(L5="", "Not Trained", IF(L5 < TODAY() - 1, "Expired", IF(L5 <= TODAY() + 90, "Expiring", "Valid") ) ) ) -> Valid | N5: 46443 | O5: =IF( _xlfn.XLOOKUP($D5 & "-" & N$2, TrainingMan!$G:$G, TrainingMan!$F:$F, "2-Year") = "Forever", "Valid", IF(N5="", "Not Trained", IF(N5 < TODAY() - 1, "Expired", IF(N5 <= TODAY() + 90, "Expiring", "Valid") ) ) ) -> Valid | P5: 46443 | Q5: =IF( _xlfn.XLOOKUP($D5 & "-" & P$2, TrainingMan!$G:$G, TrainingMan!$F:$F, "2-Year") = "Forever", "Valid", IF(P5="", "Not Trained", IF(P5 < TODAY() - 1, "Expired", IF(P5 <= TODAY() + 90, "Expiring", "Valid") ) ) ) -> Valid | R5: 46443 | S5: =IF( _xlfn.XLOOKUP($D5 & "-" & R$2, TrainingMan!$G:$G, TrainingMan!$F:$F, "2-Year") = "Forever", "Valid", IF(R5="", "Not Trained", IF(R5 < TODAY() - 1, "Expired", IF(R5 <= TODAY() + 90, "Expiring", "Valid") ) ) ) -> Valid | T5: 46443 | U5: =IF( _xlfn.XLOOKUP($D5 & "-" & T$2, TrainingMan!$G:$G, TrainingMan!$F:$F, "2-Year") = "Forever", "Valid", IF(T5="", "Not Trained", IF(T5 < TODAY() - 1, "Expired", IF(T5 <= TODAY() + 90, "Expiring", "Valid") ) ) ) -> Valid | V5: 44112 | W5: =IF( _xlfn.XLOOKUP($D5 & "-" & V$2, TrainingMan!$G:$G, TrainingMan!$F:$F, "2-Year") = "Forever", "Valid", IF(V5="", "Not Trained", IF(V5 < TODAY() - 1, "Expired", IF(V5 <= TODAY() + 90, "Expiring", "Valid") ) ) ) -> Valid | X5: 41982 | Y5: =IF( _xlfn.XLOOKUP($D5 & "-" & X$2, TrainingMan!$G:$G, TrainingMan!$F:$F, "2-Year") = "Forever", "Valid", IF(X5="", "Not Trained", IF(X5 < TODAY() - 1, "Expired", IF(X5 <= TODAY() + 90, "Expiring", "Valid") ) ) ) -> Valid | Z5: 42611 | AA5: =IF(LEN(TRIM(Z5)) = 0, "Not Trained", IF(_xlfn.XLOOKUP($D5 & "-" & Z$2, TrainingMan!$G:$G, TrainingMan!$F:$F, "2-Year") = "Forever", "Valid", IF(Z5 < TODAY() - 1, "Expired", IF(Z5 <= TODAY() + 90, "Expiring", "Valid") ) ) ) -> Valid | AD5: 45728 | AG5: 45217 | AH5: 40644 | AP5: 45268 | AQ5: 42620 | AR5: 42669 | AS5: 42842 | AU5: 45467 | BD5: 45427 | BG5: 40560 | BQ5: =COUNTIF('TrainingReq (Ach)'!B:B,Table13[[#This Row],[Job Title]]) -> 12 | BR5: {=SUMPRODUCT( COUNTIFS( ValidityMatrix[Job Title], Table13[[#This Row],[Job Title]], ValidityMatrix[Training Type], Table13[[#Headers],[Human Factor]:[Mandatory for Supporting]] ), --(Table13[[#This Row],[Human Factor]:[Mandatory for Supporting]]<>""), --(Table13[[#This Row],[Human Factor]:[Mandatory for Supporting]]<>"Not Trained") )} -> 12 | BS5: =BR5/BQ5 -> 1 | CE5: =IF( _xlfn.XLOOKUP($D5 & "-" & CD$2, 'TrainingReq (Ach)'!$G:$G, 'TrainingReq (Ach)'!$F:$F, "2-Year") = "Forever", "Valid", IF(CD5="", "Not Trained", IF(CD5 < TODAY() - 1, "Expired", IF(CD5 <= TODAY() + 90, "Expiring", "Valid") ) ) ) -> Not Trained | CH5: =IF( _xlfn.XLOOKUP($D4 & "-" & CG$2, 'TrainingReq (Ach)'!$G:$G, 'TrainingReq (Ach)'!$F:$F, "2-Year") = "Forever", "Valid", IF(CG4="", "Not Trained", IF(CG4 < TODAY() - 1, "Expired", IF(CG4 <= TODAY() + 90, "Expiring", "Valid") ) ) ) -> Not Trained | CI5: =IF(BW5<>"","Eligible","Not eligible") -> Not eligible | CJ5: =IF(BX5<>"","Eligible","Not eligible") -> Not eligible
A6: 4 | B6: 581071 | C6: JERRY HAIKAL PAPUDI | D6: AIRCRAFT CABIN ENGINEER | E6: p414 | F6: JKTTLF-1 | G6: JKTTNL-1 | H6: 46514 | I6: =IF( _xlfn.XLOOKUP($D6 & "-" & H$2, 'TrainingReq (Ach)'!G:G, 'TrainingReq (Ach)'!F:F, "2-Year") = "Forever", "Valid", IF(H6="", "Not Trained", IF(H6 < TODAY() - 1, "Expired", IF(H6 <= TODAY() + 90, "Expiring", "Valid") ) ) ) -> Valid | J6: 46514 | K6: =IF( _xlfn.XLOOKUP($D6 & "-" & J$2, 'TrainingReq (Ach)'!G:G, 'TrainingReq (Ach)'!F:F, "2-Year") = "Forever", "Valid", IF(J6="", "Not Trained", IF(J6 < TODAY() - 1, "Expired", IF(J6 <= TODAY() + 90, "Expiring", "Valid") ) ) ) -> Valid | L6: 46501 | M6: =IF( _xlfn.XLOOKUP($D6 & "-" & L$2, TrainingMan!$G:$G, TrainingMan!$F:$F, "2-Year") = "Forever", "Valid", IF(L6="", "Not Trained", IF(L6 < TODAY() - 1, "Expired", IF(L6 <= TODAY() + 90, "Expiring", "Valid") ) ) ) -> Valid | N6: 46501 | O6: =IF( _xlfn.XLOOKUP($D6 & "-" & N$2, TrainingMan!$G:$G, TrainingMan!$F:$F, "2-Year") = "Forever", "Valid", IF(N6="", "Not Trained", IF(N6 < TODAY() - 1, "Expired", IF(N6 <= TODAY() + 90, "Expiring", "Valid") ) ) ) -> Valid | P6: 46501 | Q6: =IF( _xlfn.XLOOKUP($D6 & "-" & P$2, TrainingMan!$G:$G, TrainingMan!$F:$F, "2-Year") = "Forever", "Valid", IF(P6="", "Not Trained", IF(P6 < TODAY() - 1, "Expired", IF(P6 <= TODAY() + 90, "Expiring", "Valid") ) ) ) -> Valid | R6: 46501 | S6: =IF( _xlfn.XLOOKUP($D6 & "-" & R$2, TrainingMan!$G:$G, TrainingMan!$F:$F, "2-Year") = "Forever", "Valid", IF(R6="", "Not Trained", IF(R6 < TODAY() - 1, "Expired", IF(R6 <= TODAY() + 90, "Expiring", "Valid") ) ) ) -> Valid | T6: 46501 | U6: =IF( _xlfn.XLOOKUP($D6 & "-" & T$2, TrainingMan!$G:$G, TrainingMan!$F:$F, "2-Year") = "Forever", "Valid", IF(T6="", "Not Trained", IF(T6 < TODAY() - 1, "Expired", IF(T6 <= TODAY() + 90, "Expiring", "Valid") ) ) ) -> Valid | V6: 46501 | W6: =IF( _xlfn.XLOOKUP($D6 & "-" & V$2, TrainingMan!$G:$G, TrainingMan!$F:$F, "2-Year") = "Forever", "Valid", IF(V6="", "Not Trained", IF(V6 < TODAY() - 1, "Expired", IF(V6 <= TODAY() + 90, "Expiring", "Valid") ) ) ) -> Valid | X6: 46501 | Y6: =IF( _xlfn.XLOOKUP($D6 & "-" & X$2, TrainingMan!$G:$G, TrainingMan!$F:$F, "2-Year") = "Forever", "Valid", IF(X6="", "Not Trained", IF(X6 < TODAY() - 1, "Expired", IF(X6 <= TODAY() + 90, "Expiring", "Valid") ) ) ) -> Valid | Z6: 45281 | AA6: =IF(LEN(TRIM(Z6)) = 0, "Not Trained", IF(_xlfn.XLOOKUP($D6 & "-" & Z$2, TrainingMan!$G:$G, TrainingMan!$F:$F, "2-Year") = "Forever", "Valid", IF(Z6 < TODAY() - 1, "Expired", IF(Z6 <= TODAY() + 90, "Expiring", "Valid") ) ) ) -> Valid | AB6: 42445 | AC6: 43429 | AD6: 44624 | AE6: 44620 | AF6: 45683 | BB6: 46074 | BD6: 2024-04-03 | BF6: 41991 | BI6: 45558 | BJ6: A330 | BK6: CRJ | BQ6: =COUNTIF('TrainingReq (Ach)'!B:B,Table13[[#This Row],[Job Title]]) -> 15 | BR6: {=SUMPRODUCT( COUNTIFS( ValidityMatrix[Job Title], Table13[[#This Row],[Job Title]], ValidityMatrix[Training Type], Table13[[#Headers],[Human Factor]:[Mandatory for Supporting]] ), --(Table13[[#This Row],[Human Factor]:[Mandatory for Supporting]]<>""), --(Table13[[#This Row],[Human Factor]:[Mandatory for Supporting]]<>"Not Trained") )} -> 15 | BS6: =BR6/BQ6 -> 1 | BT6: 100.00% | BU6: DIRECT | BW6: A330 | BX6: CRJ | BZ6: 10104 | CC6: I.A10104 | CD6: 47196 | CE6: =IF( _xlfn.XLOOKUP($D6 & "-" & CD$2, 'TrainingReq (Ach)'!$G:$G, 'TrainingReq (Ach)'!$F:$F, "2-Year") = "Forever", "Valid", IF(CD6="", "Not Trained", IF(CD6 < TODAY() - 1, "Expired", IF(CD6 <= TODAY() + 90, "Expiring", "Valid") ) ) ) -> Valid | CF6: A null | CG6: 54756 | CH6: =IF( _xlfn.XLOOKUP($D5 & "-" & CG$2, 'TrainingReq (Ach)'!$G:$G, 'TrainingReq (Ach)'!$F:$F, "2-Year") = "Forever", "Valid", IF(CG5="", "Not Trained", IF(CG5 < TODAY() - 1, "Expired", IF(CG5 <= TODAY() + 90, "Expiring", "Valid") ) ) ) -> Not Trained | CI6: =IF(BW6<>"","Eligible","Not eligible") -> Eligible | CJ6: =IF(BX6<>"","Eligible","Not eligible") -> Eligible
A7: 5 | B7: 532717 | C7: ANDRI PRASETYO | D7: MANAGER CABIN ON DUTY | E7: p407 | F7: JKTTLF-1 | G7: JKTTNP | H7: 46528 | I7: =IF( _xlfn.XLOOKUP($D7 & "-" & H$2, 'TrainingReq (Ach)'!G:G, 'TrainingReq (Ach)'!F:F, "2-Year") = "Forever", "Valid", IF(H7="", "Not Trained", IF(H7 < TODAY() - 1, "Expired", IF(H7 <= TODAY() + 90, "Expiring", "Valid") ) ) ) -> Valid | J7: 46528 | K7: =IF( _xlfn.XLOOKUP($D7 & "-" & J$2, 'TrainingReq (Ach)'!G:G, 'TrainingReq (Ach)'!F:F, "2-Year") = "Forever", "Valid", IF(J7="", "Not Trained", IF(J7 < TODAY() - 1, "Expired", IF(J7 <= TODAY() + 90, "Expiring", "Valid") ) ) ) -> Valid | L7: 46533 | M7: =IF( _xlfn.XLOOKUP($D7 & "-" & L$2, TrainingMan!$G:$G, TrainingMan!$F:$F, "2-Year") = "Forever", "Valid", IF(L7="", "Not Trained", IF(L7 < TODAY() - 1, "Expired", IF(L7 <= TODAY() + 90, "Expiring", "Valid") ) ) ) -> Valid | N7: 46205 | O7: =IF( _xlfn.XLOOKUP($D7 & "-" & N$2, TrainingMan!$G:$G, TrainingMan!$F:$F, "2-Year") = "Forever", "Valid", IF(N7="", "Not Trained", IF(N7 < TODAY() - 1, "Expired", IF(N7 <= TODAY() + 90, "Expiring", "Valid") ) ) ) -> Valid | P7: 46210 | Q7: =IF( _xlfn.XLOOKUP($D7 & "-" & P$2, TrainingMan!$G:$G, TrainingMan!$F:$F, "2-Year") = "Forever", "Valid", IF(P7="", "Not Trained", IF(P7 < TODAY() - 1, "Expired", IF(P7 <= TODAY() + 90, "Expiring", "Valid") ) ) ) -> Valid | R7: 46210 | S7: =IF( _xlfn.XLOOKUP($D7 & "-" & R$2, TrainingMan!$G:$G, TrainingMan!$F:$F, "2-Year") = "Forever", "Valid", IF(R7="", "Not Trained", IF(R7 < TODAY() - 1, "Expired", IF(R7 <= TODAY() + 90, "Expiring", "Valid") ) ) ) -> Valid | T7: 46210 | U7: =IF( _xlfn.XLOOKUP($D7 & "-" & T$2, TrainingMan!$G:$G, TrainingMan!$F:$F, "2-Year") = "Forever", "Valid", IF(T7="", "Not Trained", IF(T7 < TODAY() - 1, "Expired", IF(T7 <= TODAY() + 90, "Expiring", "Valid") ) ) ) -> Valid | V7: 46533 | W7: =IF( _xlfn.XLOOKUP($D7 & "-" & V$2, TrainingMan!$G:$G, TrainingMan!$F:$F, "2-Year") = "Forever", "Valid", IF(V7="", "Not Trained", IF(V7 < TODAY() - 1, "Expired", IF(V7 <= TODAY() + 90, "Expiring", "Valid") ) ) ) -> Valid | X7: 46210 | Y7: =IF( _xlfn.XLOOKUP($D7 & "-" & X$2, TrainingMan!$G:$G, TrainingMan!$F:$F, "2-Year") = "Forever", "Valid", IF(X7="", "Not Trained", IF(X7 < TODAY() - 1, "Expired", IF(X7 <= TODAY() + 90, "Expiring", "Valid") ) ) ) -> Valid | Z7: 45386 | AA7: =IF(LEN(TRIM(Z7)) = 0, "Not Trained", IF(_xlfn.XLOOKUP($D7 & "-" & Z$2, TrainingMan!$G:$G, TrainingMan!$F:$F, "2-Year") = "Forever", "Valid", IF(Z7 < TODAY() - 1, "Expired", IF(Z7 <= TODAY() + 90, "Expiring", "Valid") ) ) ) -> Valid | AB7: 40676 | AC7: 42727 | AD7: 43001 | AE7: 43134 | AF7: 43889 | AG7: 43602 | AP7: 46181 | BB7: 46311 | BC7: 2019-12-12 | BD7: 2024-12-30 | BF7: 39701 | BI7: 42877 | BJ7: A330 | BK7: A330 Neo | BM7: 2010-07-01 | BQ7: =COUNTIF('TrainingReq (Ach)'!B:B,Table13[[#This Row],[Job Title]]) -> 9 | BR7: {=SUMPRODUCT( COUNTIFS( ValidityMatrix[Job Title], Table13[[#This Row],[Job Title]], ValidityMatrix[Training Type], Table13[[#Headers],[Human Factor]:[Mandatory for Supporting]] ), --(Table13[[#This Row],[Human Factor]:[Mandatory for Supporting]]<>""), --(Table13[[#This Row],[Human Factor]:[Mandatory for Supporting]]<>"Not Trained") )} -> 9 | BS7: =BR7/BQ7 -> 1 | BT7: 100.00% | BU7: DIRECT | BV7: A1 A4 | BW7: A330 | BX7: A330 Neo | BZ7: 6685 | CC7: I.A6685 | CD7: 46253 | CE7: =IF( _xlfn.XLOOKUP($D7 & "-" & CD$2, 'TrainingReq (Ach)'!$G:$G, 'TrainingReq (Ach)'!$F:$F, "2-Year") = "Forever", "Valid", IF(CD7="", "Not Trained", IF(CD7 < TODAY() - 1, "Expired", IF(CD7 <= TODAY() + 90, "Expiring", "Valid") ) ) ) -> Expired | CF7: A null | CG7: 53559 | CH7: =IF( _xlfn.XLOOKUP($D6 & "-" & CG$2, 'TrainingReq (Ach)'!$G:$G, 'TrainingReq (Ach)'!$F:$F, "2-Year") = "Forever", "Valid", IF(CG6="", "Not Trained", IF(CG6 < TODAY() - 1, "Expired", IF(CG6 <= TODAY() + 90, "Expiring", "Valid") ) ) ) -> Valid | CI7: =IF(BW7<>"","Eligible","Not eligible") -> Eligible | CJ7: =IF(BX7<>"","Eligible","Not eligible") -> Eligible
A8: 6 | B8: 533492 | C8: SURYA ANUGRAH | D8: AIRCRAFT CABIN ENGINEER | E8: p414 | F8: JKTTLF-1 | G8: JKTTNL-1 | H8: 46581 | I8: =IF( _xlfn.XLOOKUP($D8 & "-" & H$2, 'TrainingReq (Ach)'!G:G, 'TrainingReq (Ach)'!F:F, "2-Year") = "Forever", "Valid", IF(H8="", "Not Trained", IF(H8 < TODAY() - 1, "Expired", IF(H8 <= TODAY() + 90, "Expiring", "Valid") ) ) ) -> Valid | J8: 46581 | K8: =IF( _xlfn.XLOOKUP($D8 & "-" & J$2, 'TrainingReq (Ach)'!G:G, 'TrainingReq (Ach)'!F:F, "2-Year") = "Forever", "Valid", IF(J8="", "Not Trained", IF(J8 < TODAY() - 1, "Expired", IF(J8 <= TODAY() + 90, "Expiring", "Valid") ) ) ) -> Valid | L8: 46470 | M8: =IF( _xlfn.XLOOKUP($D8 & "-" & L$2, TrainingMan!$G:$G, TrainingMan!$F:$F, "2-Year") = "Forever", "Valid", IF(L8="", "Not Trained", IF(L8 < TODAY() - 1, "Expired", IF(L8 <= TODAY() + 90, "Expiring", "Valid") ) ) ) -> Valid | N8: 46636 | O8: =IF( _xlfn.XLOOKUP($D8 & "-" & N$2, TrainingMan!$G:$G, TrainingMan!$F:$F, "2-Year") = "Forever", "Valid", IF(N8="", "Not Trained", IF(N8 < TODAY() - 1, "Expired", IF(N8 <= TODAY() + 90, "Expiring", "Valid") ) ) ) -> Valid | P8: 46636 | Q8: =IF( _xlfn.XLOOKUP($D8 & "-" & P$2, TrainingMan!$G:$G, TrainingMan!$F:$F, "2-Year") = "Forever", "Valid", IF(P8="", "Not Trained", IF(P8 < TODAY() - 1, "Expired", IF(P8 <= TODAY() + 90, "Expiring", "Valid") ) ) ) -> Valid | R8: 46636 | S8: =IF( _xlfn.XLOOKUP($D8 & "-" & R$2, TrainingMan!$G:$G, TrainingMan!$F:$F, "2-Year") = "Forever", "Valid", IF(R8="", "Not Trained", IF(R8 < TODAY() - 1, "Expired", IF(R8 <= TODAY() + 90, "Expiring", "Valid") ) ) ) -> Valid | T8: 46636 | U8: =IF( _xlfn.XLOOKUP($D8 & "-" & T$2, TrainingMan!$G:$G, TrainingMan!$F:$F, "2-Year") = "Forever", "Valid", IF(T8="", "Not Trained", IF(T8 < TODAY() - 1, "Expired", IF(T8 <= TODAY() + 90, "Expiring", "Valid") ) ) ) -> Valid | V8: 46376 | W8: =IF( _xlfn.XLOOKUP($D8 & "-" & V$2, TrainingMan!$G:$G, TrainingMan!$F:$F, "2-Year") = "Forever", "Valid", IF(V8="", "Not Trained", IF(V8 < TODAY() - 1, "Expired", IF(V8 <= TODAY() + 90, "Expiring", "Valid") ) ) ) -> Valid | X8: 46451 | Y8: =IF( _xlfn.XLOOKUP($D8 & "-" & X$2, TrainingMan!$G:$G, TrainingMan!$F:$F, "2-Year") = "Forever", "Valid", IF(X8="", "Not Trained", IF(X8 < TODAY() - 1, "Expired", IF(X8 <= TODAY() + 90, "Expiring", "Valid") ) ) ) -> Valid | Z8: 45191 | AA8: =IF(LEN(TRIM(Z8)) = 0, "Not Trained", IF(_xlfn.XLOOKUP($D8 & "-" & Z$2, TrainingMan!$G:$G, TrainingMan!$F:$F, "2-Year") = "Forever", "Valid", IF(Z8 < TODAY() - 1, "Expired", IF(Z8 <= TODAY() + 90, "Expiring", "Valid") ) ) ) -> Valid | AB8: 40856 | AC8: 43453 | AD8: 43623 | AE8: 45506 | AF8: 45338 | AG8: 45097 | BB8: 46318 | BC8: 2011-12-16 | BD8: 2024-12-30 | BI8: 44545 | BJ8: A320 | BK8: A320 Neo | BQ8: =COUNTIF('TrainingReq (Ach)'!B:B,Table13[[#This Row],[Job Title]]) -> 15 | BR8: {=SUMPRODUCT( COUNTIFS( ValidityMatrix[Job Title], Table13[[#This Row],[Job Title]], ValidityMatrix[Training Type], Table13[[#Headers],[Human Factor]:[Mandatory for Supporting]] ), --(Table13[[#This Row],[Human Factor]:[Mandatory for Supporting]]<>""), --(Table13[[#This Row],[Human Factor]:[Mandatory for Supporting]]<>"Not Trained") )} -> 15 | BS8: =BR8/BQ8 -> 1 | BT8: 100.00% | BU8: DIRECT | BV8: A1 A4 | BW8: A320 | BX8: A320 Neo | BZ8: 7163 | CA8: 2 | CC8: I.A7163 | CD8: 46813 | CE8: =IF( _xlfn.XLOOKUP($D8 & "-" & CD$2, 'TrainingReq (Ach)'!$G:$G, 'TrainingReq (Ach)'!$F:$F, "2-Year") = "Forever", "Valid", IF(CD8="", "Not Trained", IF(CD8 < TODAY() - 1, "Expired", IF(CD8 <= TODAY() + 90, "Expiring", "Valid") ) ) ) -> Valid | CF8: A null | CG8: 53885 | CH8: =IF( _xlfn.XLOOKUP($D7 & "-" & CG$2, 'TrainingReq (Ach)'!$G:$G, 'TrainingReq (Ach)'!$F:$F, "2-Year") = "Forever", "Valid", IF(CG7="", "Not Trained", IF(CG7 < TODAY() - 1, "Expired", IF(CG7 <= TODAY() + 90, "Expiring", "Valid") ) ) ) -> Valid | CI8: =IF(BW8<>"","Eligible","Not eligible") -> Eligible | CJ8: =IF(BX8<>"","Eligible","Not eligible") -> Eligible
A9: 7 | B9: 583742 | C9: PANGERAN RAIHAN RANGKUTI | D9: SENIOR AIRCRAFT MAINTENANCE TECHNICIAN | E9: p422 | F9: JKTTLF-1 | G9: JKTTNL-1 | H9: 46766 | I9: =IF( _xlfn.XLOOKUP($D9 & "-" & H$2, 'TrainingReq (Ach)'!G:G, 'TrainingReq (Ach)'!F:F, "2-Year") = "Forever", "Valid", IF(H9="", "Not Trained", IF(H9 < TODAY() - 1, "Expired", IF(H9 <= TODAY() + 90, "Expiring", "Valid") ) ) ) -> Valid | J9: 46766 | K9: =IF( _xlfn.XLOOKUP($D9 & "-" & J$2, 'TrainingReq (Ach)'!G:G, 'TrainingReq (Ach)'!F:F, "2-Year") = "Forever", "Valid", IF(J9="", "Not Trained", IF(J9 < TODAY() - 1, "Expired", IF(J9 <= TODAY() + 90, "Expiring", "Valid") ) ) ) -> Valid | L9: 46813 | M9: =IF( _xlfn.XLOOKUP($D9 & "-" & L$2, TrainingMan!$G:$G, TrainingMan!$F:$F, "2-Year") = "Forever", "Valid", IF(L9="", "Not Trained", IF(L9 < TODAY() - 1, "Expired", IF(L9 <= TODAY() + 90, "Expiring", "Valid") ) ) ) -> Valid | N9: 46813 | O9: =IF( _xlfn.XLOOKUP($D9 & "-" & N$2, TrainingMan!$G:$G, TrainingMan!$F:$F, "2-Year") = "Forever", "Valid", IF(N9="", "Not Trained", IF(N9 < TODAY() - 1, "Expired", IF(N9 <= TODAY() + 90, "Expiring", "Valid") ) ) ) -> Valid | P9: 46813 | Q9: =IF( _xlfn.XLOOKUP($D9 & "-" & P$2, TrainingMan!$G:$G, TrainingMan!$F:$F, "2-Year") = "Forever", "Valid", IF(P9="", "Not Trained", IF(P9 < TODAY() - 1, "Expired", IF(P9 <= TODAY() + 90, "Expiring", "Valid") ) ) ) -> Valid | R9: 46813 | S9: =IF( _xlfn.XLOOKUP($D9 & "-" & R$2, TrainingMan!$G:$G, TrainingMan!$F:$F, "2-Year") = "Forever", "Valid", IF(R9="", "Not Trained", IF(R9 < TODAY() - 1, "Expired", IF(R9 <= TODAY() + 90, "Expiring", "Valid") ) ) ) -> Valid | T9: 46813 | U9: =IF( _xlfn.XLOOKUP($D9 & "-" & T$2, TrainingMan!$G:$G, TrainingMan!$F:$F, "2-Year") = "Forever", "Valid", IF(T9="", "Not Trained", IF(T9 < TODAY() - 1, "Expired", IF(T9 <= TODAY() + 90, "Expiring", "Valid") ) ) ) -> Valid | V9: 46645 | W9: =IF( _xlfn.XLOOKUP($D9 & "-" & V$2, TrainingMan!$G:$G, TrainingMan!$F:$F, "2-Year") = "Forever", "Valid", IF(V9="", "Not Trained", IF(V9 < TODAY() - 1, "Expired", IF(V9 <= TODAY() + 90, "Expiring", "Valid") ) ) ) -> Valid | X9: 46575 | Y9: =IF( _xlfn.XLOOKUP($D9 & "-" & X$2, TrainingMan!$G:$G, TrainingMan!$F:$F, "2-Year") = "Forever", "Valid", IF(X9="", "Not Trained", IF(X9 < TODAY() - 1, "Expired", IF(X9 <= TODAY() + 90, "Expiring", "Valid") ) ) ) -> Valid | Z9: 45304 | AA9: =IF(LEN(TRIM(Z9)) = 0, "Not Trained", IF(_xlfn.XLOOKUP($D9 & "-" & Z$2, TrainingMan!$G:$G, TrainingMan!$F:$F, "2-Year") = "Forever", "Valid", IF(Z9 < TODAY() - 1, "Expired", IF(Z9 <= TODAY() + 90, "Expiring", "Valid") ) ) ) -> Valid | AB9: 45452 | AD9: 45702 | AF9: 46076 | BB9: 46068 | BC9: 2022-11-09 | BD9: 45840 | BF9: 42996 | BI9: 45526 | BJ9: A320 | BQ9: =COUNTIF('TrainingReq (Ach)'!B:B,Table13[[#This Row],[Job Title]]) -> 15 | BR9: {=SUMPRODUCT( COUNTIFS( ValidityMatrix[Job Title], Table13[[#This Row],[Job Title]], ValidityMatrix[Training Type], Table13[[#Headers],[Human Factor]:[Mandatory for Supporting]] ), --(Table13[[#This Row],[Human Factor]:[Mandatory for Supporting]]<>""), --(Table13[[#This Row],[Human Factor]:[Mandatory for Supporting]]<>"Not Trained") )} -> 14 | BS9: =BR9/BQ9 -> 0.93333333 | BT9: 92.31% | BU9: DIRECT | BV9: A1 A4 | CC9: M.583742 | CE9: =IF( _xlfn.XLOOKUP($D9 & "-" & CD$2, 'TrainingReq (Ach)'!$G:$G, 'TrainingReq (Ach)'!$F:$F, "2-Year") = "Forever", "Valid", IF(CD9="", "Not Trained", IF(CD9 < TODAY() - 1, "Expired", IF(CD9 <= TODAY() + 90, "Expiring", "Valid") ) ) ) -> Not Trained | CF9: A null | CG9: 56983 | CH9: =IF( _xlfn.XLOOKUP($D8 & "-" & CG$2, 'TrainingReq (Ach)'!$G:$G, 'TrainingReq (Ach)'!$F:$F, "2-Year") = "Forever", "Valid", IF(CG8="", "Not Trained", IF(CG8 < TODAY() - 1, "Expired", IF(CG8 <= TODAY() + 90, "Expiring", "Valid") ) ) ) -> Valid | CI9: =IF(BW9<>"","Eligible","Not eligible") -> Not eligible | CJ9: =IF(BX9<>"","Eligible","Not eligible") -> Not eligible
A10: 8 | B10: 582541 | C10: WAHYU P BUDIMAN | D10: SENIOR AIRCRAFT MAINTENANCE TECHNICIAN | E10: p422 | F10: JKTTLF-1 | G10: JKTTNL-5 | H10: 46794 | I10: =IF( _xlfn.XLOOKUP($D10 & "-" & H$2, 'TrainingReq (Ach)'!G:G, 'TrainingReq (Ach)'!F:F, "2-Year") = "Forever", "Valid", IF(H10="", "Not Trained", IF(H10 < TODAY() - 1, "Expired", IF(H10 <= TODAY() + 90, "Expiring", "Valid") ) ) ) -> Valid | J10: 46794 | K10: =IF( _xlfn.XLOOKUP($D10 & "-" & J$2, 'TrainingReq (Ach)'!G:G, 'TrainingReq (Ach)'!F:F, "2-Year") = "Forever", "Valid", IF(J10="", "Not Trained", IF(J10 < TODAY() - 1, "Expired", IF(J10 <= TODAY() + 90, "Expiring", "Valid") ) ) ) -> Valid | L10: 46845 | M10: =IF( _xlfn.XLOOKUP($D10 & "-" & L$2, TrainingMan!$G:$G, TrainingMan!$F:$F, "2-Year") = "Forever", "Valid", IF(L10="", "Not Trained", IF(L10 < TODAY() - 1, "Expired", IF(L10 <= TODAY() + 90, "Expiring", "Valid") ) ) ) -> Valid | N10: 46845 | O10: =IF( _xlfn.XLOOKUP($D10 & "-" & N$2, TrainingMan!$G:$G, TrainingMan!$F:$F, "2-Year") = "Forever", "Valid", IF(N10="", "Not Trained", IF(N10 < TODAY() - 1, "Expired", IF(N10 <= TODAY() + 90, "Expiring", "Valid") ) ) ) -> Valid | P10: 46845 | Q10: =IF( _xlfn.XLOOKUP($D10 & "-" & P$2, TrainingMan!$G:$G, TrainingMan!$F:$F, "2-Year") = "Forever", "Valid", IF(P10="", "Not Trained", IF(P10 < TODAY() - 1, "Expired", IF(P10 <= TODAY() + 90, "Expiring", "Valid") ) ) ) -> Valid | R10: 46845 | S10: =IF( _xlfn.XLOOKUP($D10 & "-" & R$2, TrainingMan!$G:$G, TrainingMan!$F:$F, "2-Year") = "Forever", "Valid", IF(R10="", "Not Trained", IF(R10 < TODAY() - 1, "Expired", IF(R10 <= TODAY() + 90, "Expiring", "Valid") ) ) ) -> Valid | T10: 46845 | U10: =IF( _xlfn.XLOOKUP($D10 & "-" & T$2, TrainingMan!$G:$G, TrainingMan!$F:$F, "2-Year") = "Forever", "Valid", IF(T10="", "Not Trained", IF(T10 < TODAY() - 1, "Expired", IF(T10 <= TODAY() + 90, "Expiring", "Valid") ) ) ) -> Valid | V10: 46845 | W10: =IF( _xlfn.XLOOKUP($D10 & "-" & V$2, TrainingMan!$G:$G, TrainingMan!$F:$F, "2-Year") = "Forever", "Valid", IF(V10="", "Not Trained", IF(V10 < TODAY() - 1, "Expired", IF(V10 <= TODAY() + 90, "Expiring", "Valid") ) ) ) -> Valid | X10: 46845 | Y10: =IF( _xlfn.XLOOKUP($D10 & "-" & X$2, TrainingMan!$G:$G, TrainingMan!$F:$F, "2-Year") = "Forever", "Valid", IF(X10="", "Not Trained", IF(X10 < TODAY() - 1, "Expired", IF(X10 <= TODAY() + 90, "Expiring", "Valid") ) ) ) -> Valid | Z10: 45397 | AA10: =IF(LEN(TRIM(Z10)) = 0, "Not Trained", IF(_xlfn.XLOOKUP($D10 & "-" & Z$2, TrainingMan!$G:$G, TrainingMan!$F:$F, "2-Year") = "Forever", "Valid", IF(Z10 < TODAY() - 1, "Expired", IF(Z10 <= TODAY() + 90, "Expiring", "Valid") ) ) ) -> Valid | AB10: 44618 | AC10: 45716 | AD10: 44456 | AE10: 45058 | AF10: 44834 | AG10: 45139 | AT10: 46076 | BB10: 46255 | BC10: 2017-10-26 | BD10: 2017-10-11 | BI10: 44165 | BJ10: A320 | BK10: A320 Neo | BQ10: =COUNTIF('TrainingReq (Ach)'!B:B,Table13[[#This Row],[Job Title]]) -> 15 | BR10: {=SUMPRODUCT( COUNTIFS( ValidityMatrix[Job Title], Table13[[#This Row],[Job Title]], ValidityMatrix[Training Type], Table13[[#Headers],[Human Factor]:[Mandatory for Supporting]] ), --(Table13[[#This Row],[Human Factor]:[Mandatory for Supporting]]<>""), --(Table13[[#This Row],[Human Factor]:[Mandatory for Supporting]]<>"Not Trained") )} -> 15 | BS10: =BR10/BQ10 -> 1 | BT10: 100.00% | BU10: DIRECT | BV10: C1 C2 C4 | BW10: A320 | BX10: A320 Neo | BZ10: 15347 | CC10: I.E15347 | CD10: 47078 | CE10: =IF( _xlfn.XLOOKUP($D10 & "-" & CD$2, 'TrainingReq (Ach)'!$G:$G, 'TrainingReq (Ach)'!$F:$F, "2-Year") = "Forever", "Valid", IF(CD10="", "Not Trained", IF(CD10 < TODAY() - 1, "Expired", IF(CD10 <= TODAY() + 90, "Expiring", "Valid") ) ) ) -> Valid | CF10: A null | CG10: 56195 | CH10: =IF( _xlfn.XLOOKUP($D9 & "-" & CG$2, 'TrainingReq (Ach)'!$G:$G, 'TrainingReq (Ach)'!$F:$F, "2-Year") = "Forever", "Valid", IF(CG9="", "Not Trained", IF(CG9 < TODAY() - 1, "Expired", IF(CG9 <= TODAY() + 90, "Expiring", "Valid") ) ) ) -> Valid | CI10: =IF(BW10<>"","Eligible","Not eligible") -> Eligible | CJ10: =IF(BX10<>"","Eligible","Not eligible") -> Eligible
A11: 9 | B11: 581765 | C11: HERDANI INDERA PERMANA | D11: AIRCRAFT CABIN ENGINEER | E11: p414 | F11: JKTTLF-1 | G11: JKTTNL-1 | H11: 46851 | I11: =IF( _xlfn.XLOOKUP($D11 & "-" & H$2, 'TrainingReq (Ach)'!G:G, 'TrainingReq (Ach)'!F:F, "2-Year") = "Forever", "Valid", IF(H11="", "Not Trained", IF(H11 < TODAY() - 1, "Expired", IF(H11 <= TODAY() + 90, "Expiring", "Valid") ) ) ) -> Valid | J11: 46851 | K11: =IF( _xlfn.XLOOKUP($D11 & "-" & J$2, 'TrainingReq (Ach)'!G:G, 'TrainingReq (Ach)'!F:F, "2-Year") = "Forever", "Valid", IF(J11="", "Not Trained", IF(J11 < TODAY() - 1, "Expired", IF(J11 <= TODAY() + 90, "Expiring", "Valid") ) ) ) -> Valid | L11: 46795 | M11: =IF( _xlfn.XLOOKUP($D11 & "-" & L$2, TrainingMan!$G:$G, TrainingMan!$F:$F, "2-Year") = "Forever", "Valid", IF(L11="", "Not Trained", IF(L11 < TODAY() - 1, "Expired", IF(L11 <= TODAY() + 90, "Expiring", "Valid") ) ) ) -> Valid | N11: 46795 | O11: =IF( _xlfn.XLOOKUP($D11 & "-" & N$2, TrainingMan!$G:$G, TrainingMan!$F:$F, "2-Year") = "Forever", "Valid", IF(N11="", "Not Trained", IF(N11 < TODAY() - 1, "Expired", IF(N11 <= TODAY() + 90, "Expiring", "Valid") ) ) ) -> Valid | P11: 46795 | Q11: =IF( _xlfn.XLOOKUP($D11 & "-" & P$2, TrainingMan!$G:$G, TrainingMan!$F:$F, "2-Year") = "Forever", "Valid", IF(P11="", "Not Trained", IF(P11 < TODAY() - 1, "Expired", IF(P11 <= TODAY() + 90, "Expiring", "Valid") ) ) ) -> Valid | R11: 46795 | S11: =IF( _xlfn.XLOOKUP($D11 & "-" & R$2, TrainingMan!$G:$G, TrainingMan!$F:$F, "2-Year") = "Forever", "Valid", IF(R11="", "Not Trained", IF(R11 < TODAY() - 1, "Expired", IF(R11 <= TODAY() + 90, "Expiring", "Valid") ) ) ) -> Valid | T11: 46795 | U11: =IF( _xlfn.XLOOKUP($D11 & "-" & T$2, TrainingMan!$G:$G, TrainingMan!$F:$F, "2-Year") = "Forever", "Valid", IF(T11="", "Not Trained", IF(T11 < TODAY() - 1, "Expired", IF(T11 <= TODAY() + 90, "Expiring", "Valid") ) ) ) -> Valid | V11: 46795 | W11: =IF( _xlfn.XLOOKUP($D11 & "-" & V$2, TrainingMan!$G:$G, TrainingMan!$F:$F, "2-Year") = "Forever", "Valid", IF(V11="", "Not Trained", IF(V11 < TODAY() - 1, "Expired", IF(V11 <= TODAY() + 90, "Expiring", "Valid") ) ) ) -> Valid | X11: 46795 | Y11: =IF( _xlfn.XLOOKUP($D11 & "-" & X$2, TrainingMan!$G:$G, TrainingMan!$F:$F, "2-Year") = "Forever", "Valid", IF(X11="", "Not Trained", IF(X11 < TODAY() - 1, "Expired", IF(X11 <= TODAY() + 90, "Expiring", "Valid") ) ) ) -> Valid | Z11: 45390 | AA11: =IF(LEN(TRIM(Z11)) = 0, "Not Trained", IF(_xlfn.XLOOKUP($D11 & "-" & Z$2, TrainingMan!$G:$G, TrainingMan!$F:$F, "2-Year") = "Forever", "Valid", IF(Z11 < TODAY() - 1, "Expired", IF(Z11 <= TODAY() + 90, "Expiring", "Valid") ) ) ) -> Valid | AB11: 43579 | AC11: 43969 | AD11: 44779 | AE11: 45355 | AF11: 45331 | AG11: 45006 | BB11: 46096 | BC11: 2022-09-16 | BD11: 2018-04-11 | BI11: 44467 | BJ11: A330 | BK11: A330 Neo | BQ11: =COUNTIF('TrainingReq (Ach)'!B:B,Table13[[#This Row],[Job Title]]) -> 15 | BR11: {=SUMPRODUCT( COUNTIFS( ValidityMatrix[Job Title], Table13[[#This Row],[Job Title]], ValidityMatrix[Training Type], Table13[[#Headers],[Human Factor]:[Mandatory for Supporting]] ), --(Table13[[#This Row],[Human Factor]:[Mandatory for Supporting]]<>""), --(Table13[[#This Row],[Human Factor]:[Mandatory for Supporting]]<>"Not Trained") )} -> 15 | BS11: =BR11/BQ11 -> 1 | BT11: 100.00% | BU11: DIRECT | BV11: A1 A3 A4 | BW11: A330 | BX11: A330 Neo | BZ11: 10480 | CC11: I.A10480 | CD11: 47097 | CE11: =IF( _xlfn.XLOOKUP($D11 & "-" & CD$2, 'TrainingReq (Ach)'!$G:$G, 'TrainingReq (Ach)'!$F:$F, "2-Year") = "Forever", "Valid", IF(CD11="", "Not Trained", IF(CD11 < TODAY() - 1, "Expired", IF(CD11 <= TODAY() + 90, "Expiring", "Valid") ) ) ) -> Valid | CF11: A null | CG11: 55002 | CH11: =IF( _xlfn.XLOOKUP($D10 & "-" & CG$2, 'TrainingReq (Ach)'!$G:$G, 'TrainingReq (Ach)'!$F:$F, "2-Year") = "Forever", "Valid", IF(CG10="", "Not Trained", IF(CG10 < TODAY() - 1, "Expired", IF(CG10 <= TODAY() + 90, "Expiring", "Valid") ) ) ) -> Valid | CI11: =IF(BW11<>"","Eligible","Not eligible") -> Eligible | CJ11: =IF(BX11<>"","Eligible","Not eligible") -> Eligible
A12: 10 | B12: 582542 | C12: FAHRUR | D12: SENIOR AIRCRAFT MAINTENANCE TECHNICIAN | E12: p422 | F12: JKTTLF-1 | G12: JKTTNL-1 | H12: 46858 | I12: =IF( _xlfn.XLOOKUP($D12 & "-" & H$2, 'TrainingReq (Ach)'!G:G, 'TrainingReq (Ach)'!F:F, "2-Year") = "Forever", "Valid", IF(H12="", "Not Trained", IF(H12 < TODAY() - 1, "Expired", IF(H12 <= TODAY() + 90, "Expiring", "Valid") ) ) ) -> Valid | J12: 46858 | K12: =IF( _xlfn.XLOOKUP($D12 & "-" & J$2, 'TrainingReq (Ach)'!G:G, 'TrainingReq (Ach)'!F:F, "2-Year") = "Forever", "Valid", IF(J12="", "Not Trained", IF(J12 < TODAY() - 1, "Expired", IF(J12 <= TODAY() + 90, "Expiring", "Valid") ) ) ) -> Valid | L12: 46898 | M12: =IF( _xlfn.XLOOKUP($D12 & "-" & L$2, TrainingMan!$G:$G, TrainingMan!$F:$F, "2-Year") = "Forever", "Valid", IF(L12="", "Not Trained", IF(L12 < TODAY() - 1, "Expired", IF(L12 <= TODAY() + 90, "Expiring", "Valid") ) ) ) -> Valid | N12: 46898 | O12: =IF( _xlfn.XLOOKUP($D12 & "-" & N$2, TrainingMan!$G:$G, TrainingMan!$F:$F, "2-Year") = "Forever", "Valid", IF(N12="", "Not Trained", IF(N12 < TODAY() - 1, "Expired", IF(N12 <= TODAY() + 90, "Expiring", "Valid") ) ) ) -> Valid | P12: 46898 | Q12: =IF( _xlfn.XLOOKUP($D12 & "-" & P$2, TrainingMan!$G:$G, TrainingMan!$F:$F, "2-Year") = "Forever", "Valid", IF(P12="", "Not Trained", IF(P12 < TODAY() - 1, "Expired", IF(P12 <= TODAY() + 90, "Expiring", "Valid") ) ) ) -> Valid | R12: 46898 | S12: =IF( _xlfn.XLOOKUP($D12 & "-" & R$2, TrainingMan!$G:$G, TrainingMan!$F:$F, "2-Year") = "Forever", "Valid", IF(R12="", "Not Trained", IF(R12 < TODAY() - 1, "Expired", IF(R12 <= TODAY() + 90, "Expiring", "Valid") ) ) ) -> Valid | T12: 46898 | U12: =IF( _xlfn.XLOOKUP($D12 & "-" & T$2, TrainingMan!$G:$G, TrainingMan!$F:$F, "2-Year") = "Forever", "Valid", IF(T12="", "Not Trained", IF(T12 < TODAY() - 1, "Expired", IF(T12 <= TODAY() + 90, "Expiring", "Valid") ) ) ) -> Valid | V12: 46898 | W12: =IF( _xlfn.XLOOKUP($D12 & "-" & V$2, TrainingMan!$G:$G, TrainingMan!$F:$F, "2-Year") = "Forever", "Valid", IF(V12="", "Not Trained", IF(V12 < TODAY() - 1, "Expired", IF(V12 <= TODAY() + 90, "Expiring", "Valid") ) ) ) -> Valid | X12: 46898 | Y12: =IF( _xlfn.XLOOKUP($D12 & "-" & X$2, TrainingMan!$G:$G, TrainingMan!$F:$F, "2-Year") = "Forever", "Valid", IF(X12="", "Not Trained", IF(X12 < TODAY() - 1, "Expired", IF(X12 <= TODAY() + 90, "Expiring", "Valid") ) ) ) -> Valid | Z12: 45451 | AA12: =IF(LEN(TRIM(Z12)) = 0, "Not Trained", IF(_xlfn.XLOOKUP($D12 & "-" & Z$2, TrainingMan!$G:$G, TrainingMan!$F:$F, "2-Year") = "Forever", "Valid", IF(Z12 < TODAY() - 1, "Expired", IF(Z12 <= TODAY() + 90, "Expiring", "Valid") ) ) ) -> Valid | AB12: 43742 | AC12: 45548 | AD12: 44589 | AE12: 45096 | AF12: 44644 | AG12: 45412 | BB12: 45997 | BC12: 2022-03-10 | BD12: 2017-10-11 | BI12: 44263 | BJ12: B737 | BN12: 2023-10-27 | BQ12: =COUNTIF('TrainingReq (Ach)'!B:B,Table13[[#This Row],[Job Title]]) -> 15 | BR12: {=SUMPRODUCT( COUNTIFS( ValidityMatrix[Job Title], Table13[[#This Row],[Job Title]], ValidityMatrix[Training Type], Table13[[#Headers],[Human Factor]:[Mandatory for Supporting]] ), --(Table13[[#This Row],[Human Factor]:[Mandatory for Supporting]]<>""), --(Table13[[#This Row],[Human Factor]:[Mandatory for Supporting]]<>"Not Trained") )} -> 15 | BS12: =BR12/BQ12 -> 1 | BT12: 100.00% | BU12: DIRECT | BV12: C1 C2 C4 | BW12: B737 | BZ12: 15473 | CB12: 13763 | CC12: I.E15473 | CD12: 47153 | CE12: =IF( _xlfn.XLOOKUP($D12 & "-" & CD$2, 'TrainingReq (Ach)'!$G:$G, 'TrainingReq (Ach)'!$F:$F, "2-Year") = "Forever", "Valid", IF(CD12="", "Not Trained", IF(CD12 < TODAY() - 1, "Expired", IF(CD12 <= TODAY() + 90, "Expiring", "Valid") ) ) ) -> Valid | CF12: A null | CG12: 55891 | CH12: =IF( _xlfn.XLOOKUP($D11 & "-" & CG$2, 'TrainingReq (Ach)'!$G:$G, 'TrainingReq (Ach)'!$F:$F, "2-Year") = "Forever", "Valid", IF(CG11="", "Not Trained", IF(CG11 < TODAY() - 1, "Expired", IF(CG11 <= TODAY() + 90, "Expiring", "Valid") ) ) ) -> Valid | CI12: =IF(BW12<>"","Eligible","Not eligible") -> Eligible | CJ12: =IF(BX12<>"","Eligible","Not eligible") -> Not eligible
A13: 11 | B13: 533498 | C13: GIANJAR D.ABIYOGA | D13: Department Head | E13: p404 | F13: JKTTLF-1 | G13: JKTTNL-1 | H13: 46956 | I13: =IF( _xlfn.XLOOKUP($D13 & "-" & H$2, 'TrainingReq (Ach)'!G:G, 'TrainingReq (Ach)'!F:F, "2-Year") = "Forever", "Valid", IF(H13="", "Not Trained", IF(H13 < TODAY() - 1, "Expired", IF(H13 <= TODAY() + 90, "Expiring", "Valid") ) ) ) -> Valid | J13: 46956 | K13: =IF( _xlfn.XLOOKUP($D13 & "-" & J$2, 'TrainingReq (Ach)'!G:G, 'TrainingReq (Ach)'!F:F, "2-Year") = "Forever", "Valid", IF(J13="", "Not Trained", IF(J13 < TODAY() - 1, "Expired", IF(J13 <= TODAY() + 90, "Expiring", "Valid") ) ) ) -> Valid | L13: 46368 | M13: =IF( _xlfn.XLOOKUP($D13 & "-" & L$2, TrainingMan!$G:$G, TrainingMan!$F:$F, "2-Year") = "Forever", "Valid", IF(L13="", "Not Trained", IF(L13 < TODAY() - 1, "Expired", IF(L13 <= TODAY() + 90, "Expiring", "Valid") ) ) ) -> Valid | N13: 46368 | O13: =IF( _xlfn.XLOOKUP($D13 & "-" & N$2, TrainingMan!$G:$G, TrainingMan!$F:$F, "2-Year") = "Forever", "Valid", IF(N13="", "Not Trained", IF(N13 < TODAY() - 1, "Expired", IF(N13 <= TODAY() + 90, "Expiring", "Valid") ) ) ) -> Valid | P13: 46305 | Q13: =IF( _xlfn.XLOOKUP($D13 & "-" & P$2, TrainingMan!$G:$G, TrainingMan!$F:$F, "2-Year") = "Forever", "Valid", IF(P13="", "Not Trained", IF(P13 < TODAY() - 1, "Expired", IF(P13 <= TODAY() + 90, "Expiring", "Valid") ) ) ) -> Expiring | R13: 46368 | S13: =IF( _xlfn.XLOOKUP($D13 & "-" & R$2, TrainingMan!$G:$G, TrainingMan!$F:$F, "2-Year") = "Forever", "Valid", IF(R13="", "Not Trained", IF(R13 < TODAY() - 1, "Expired", IF(R13 <= TODAY() + 90, "Expiring", "Valid") ) ) ) -> Valid | T13: 46305 | U13: =IF( _xlfn.XLOOKUP($D13 & "-" & T$2, TrainingMan!$G:$G, TrainingMan!$F:$F, "2-Year") = "Forever", "Valid", IF(T13="", "Not Trained", IF(T13 < TODAY() - 1, "Expired", IF(T13 <= TODAY() + 90, "Expiring", "Valid") ) ) ) -> Expiring | V13: 46598 | W13: =IF( _xlfn.XLOOKUP($D13 & "-" & V$2, TrainingMan!$G:$G, TrainingMan!$F:$F, "2-Year") = "Forever", "Valid", IF(V13="", "Not Trained", IF(V13 < TODAY() - 1, "Expired", IF(V13 <= TODAY() + 90, "Expiring", "Valid") ) ) ) -> Valid | X13: 46598 | Y13: =IF( _xlfn.XLOOKUP($D13 & "-" & X$2, TrainingMan!$G:$G, TrainingMan!$F:$F, "2-Year") = "Forever", "Valid", IF(X13="", "Not Trained", IF(X13 < TODAY() - 1, "Expired", IF(X13 <= TODAY() + 90, "Expiring", "Valid") ) ) ) -> Valid | Z13: 44443 | AA13: =IF(LEN(TRIM(Z13)) = 0, "Not Trained", IF(_xlfn.XLOOKUP($D13 & "-" & Z$2, TrainingMan!$G:$G, TrainingMan!$F:$F, "2-Year") = "Forever", "Valid", IF(Z13 < TODAY() - 1, "Expired", IF(Z13 <= TODAY() + 90, "Expiring", "Valid") ) ) ) -> Valid | AB13: 40851 | AC13: 42517 | AD13: 42837 | AE13: 44529 | AF13: 44230 | AG13: 44782 | AP13: 45882 | AQ13: 46366 | AR13: 46074 | AS13: 46290 | BC13: 2011-12-16 | BD13: 2024-04-03 | BI13: 43019 | BJ13: B777 | BQ13: =COUNTIF('TrainingReq (Ach)'!B:B,Table13[[#This Row],[Job Title]]) -> 14 | BR13: {=SUMPRODUCT( COUNTIFS( ValidityMatrix[Job Title], Table13[[#This Row],[Job Title]], ValidityMatrix[Training Type], Table13[[#Headers],[Human Factor]:[Mandatory for Supporting]] ), --(Table13[[#This Row],[Human Factor]:[Mandatory for Supporting]]<>""), --(Table13[[#This Row],[Human Factor]:[Mandatory for Supporting]]<>"Not Trained") )} -> 14 | BS13: =BR13/BQ13 -> 1 | BT13: 100.00% | BU13: INDIRECT | BV13: A1 A4 | BW13: B777 | BZ13: 8149 | CC13: I.A8149 | CD13: 46294 | CE13: =IF( _xlfn.XLOOKUP($D13 & "-" & CD$2, 'TrainingReq (Ach)'!$G:$G, 'TrainingReq (Ach)'!$F:$F, "2-Year") = "Forever", "Valid", IF(CD13="", "Not Trained", IF(CD13 < TODAY() - 1, "Expired", IF(CD13 <= TODAY() + 90, "Expiring", "Valid") ) ) ) -> Expiring | CF13: A null | CG13: 53549 | CH13: =IF( _xlfn.XLOOKUP($D12 & "-" & CG$2, 'TrainingReq (Ach)'!$G:$G, 'TrainingReq (Ach)'!$F:$F, "2-Year") = "Forever", "Valid", IF(CG12="", "Not Trained", IF(CG12 < TODAY() - 1, "Expired", IF(CG12 <= TODAY() + 90, "Expiring", "Valid") ) ) ) -> Valid | CI13: =IF(BW13<>"","Eligible","Not eligible") -> Eligible | CJ13: =IF(BX13<>"","Eligible","Not eligible") -> Not eligible
